Workbook
Name CFG_FECHA: CONFIG!$C$10
Name CFG_ANIO: CONFIG!$C$11
Name CFG_CAPITAL: CONFIG!$C$12
Name CFG_RESERVA: CONFIG!$C$13
Name CFG_RES_APERTURA: CONFIG!$C$14
Name CFG_CITI: CONFIG!$C$15
Name CFG_WALMART: CONFIG!$C$16
Name CFG_MARGEN: CONFIG!$C$17
Name LST_PAGO_COMPRA: CONFIG!$F$7:$F$8
Name LST_PAGO_GASTO: CONFIG!$G$7:$G$9
Name LST_CATEGORIAS: CONFIG!$H$7:$H$16
Name LST_MOV_WALMART: CONFIG!$I$7:$I$9
Name LST_MOV_BANCO: CONFIG!$J$7:$J$10

Sheet DASHBOARD
B1: COTIMIX · DASHBOARD FINANCIERO EJECUTIVO
B2: ="Walmart Marketplace · Actualizado al "&TEXT(TODAY(),"dd/mm/yyyy")&" · Cifras en USD"
B5: POSICIÓN FINANCIERA
B6: CAPITAL INVERTIDO | E6: EFECTIVO DISPONIBLE | H6: RESERVA WALMART | K6: VALOR DEL INVENTARIO
B7: =CFG_CAPITAL | E7: =BANCO!E13 | H7: =WALMART!E9 | K7: =INVENTARIO!M27
B8: Aporte inicial del propietario | E8: Dinero listo para operar | H8: Propio · NO disponible aún | K8: =TEXT(INVENTARIO!H27,"#,##0")&" unidades a costo real"
B10: ACTIVOS TOTALES | E10: DEUDA TARJETA CITI | H10: PATRIMONIO NETO | K10: WALMART POR LIQUIDAR
B11: =BALANCE!C11 | E11: =BALANCE!C15 | H11: =BALANCE!C22 | K11: =WALMART!E18
B12: Efectivo + Walmart + Inventario | E12: =IF(BALANCE!C15>0,"Pendiente de pago","Sin deuda") | H12: Activos − Pasivos | K12: Próximo depósito estimado
B14: DESEMPEÑO COMERCIAL (acumulado desde la apertura)
B15: VENTAS BRUTAS | E15: UTILIDAD BRUTA | H15: UTILIDAD NETA | K15: MARGEN NETO
B16: =ESTADO_RESULTADOS!Q8 | E16: =ESTADO_RESULTADOS!Q13 | H16: =ESTADO_RESULTADOS!Q29 | K16: =IF(ESTADO_RESULTADOS!Q8>0,ESTADO_RESULTADOS!Q29/ESTADO_RESULTADOS!Q8,0)
B17: =TEXT(ESTADO_RESULTADOS!Q31,"#,##0")&" unidades vendidas" | E17: Después de comisiones y costo | H17: Después de gastos operativos | K17: ="Objetivo: "&TEXT(CFG_MARGEN,"0%")
B19: ALERTAS Y CONTROLES | I19: ¿DÓNDE ESTÁ EL DINERO DE COTIMIX?
B20: Cuadre del balance | E20: =BALANCE!D25 | I20: Efectivo / Banco | K20: =MAX(BALANCE!C7,0) | L20: =IF(SUM($K$20:$K$23)>0,K20/SUM($K$20:$K$23),0) | M20: =L20
B21: Productos sin precio de venta | E21: =COUNTIFS(INVENTARIO!$B$7:$B$26,"<>",INVENTARIO!$N$7:$N$26,"")&" producto(s)" | I21: Walmart por liquidar | K21: =MAX(BALANCE!C8,0) | L21: =IF(SUM($K$20:$K$23)>0,K21/SUM($K$20:$K$23),0) | M21: =L21
B22: Productos por reordenar / agotados | E22: =COUNTIF(INVENTARIO!$J$7:$J$26,"REORDENAR")&" por reordenar · "&COUNTIF(INVENTARIO!$J$7:$J$26,"AGOTADO")&" agotado(s)" | I22: Reserva Walmart | K22: =MAX(BALANCE!C9,0) | L22: =IF(SUM($K$20:$K$23)>0,K22/SUM($K$20:$K$23),0) | M22: =L22
B23: Margen por debajo del objetivo | E23: =COUNTIFS(INVENTARIO!$S$7:$S$26,"<"&CFG_MARGEN,INVENTARIO!$N$7:$N$26,"<>")&" producto(s)" | I23: Inventario | K23: =MAX(BALANCE!C10,0) | L23: =IF(SUM($K$20:$K$23)>0,K23/SUM($K$20:$K$23),0) | M23: =L23
B24: Liquidez inmediata (efectivo ÷ deuda) | E24: =IF(BALANCE!C15>0,TEXT(BALANCE!C28,"0.00")&"x"&IF(BALANCE!C28>=1," ✔ cubre la deuda"," ⚠ no cubre la deuda"),"Sin deuda")
B25: Dinero total de COTIMIX (efectivo + Walmart) | E25: =TEXT(BALANCE!C7+BALANCE!C8+BALANCE!C9,"$#,##0.00")
B27: INVENTARIO Y RENTABILIDAD POR PRODUCTO
B28: Producto | D28: Stock | E28: Costo real unitario | F28: Precio venta | G28: Utilidad unitaria | H28: Margen neto | I28: Valor inventario | J28: Unid. vendidas | K28: Precio sugerido | L28: Estado
B29: =IF(INVENTARIO!B7="","",INVENTARIO!C7) | D29: =IF(INVENTARIO!B7="","",INVENTARIO!H7) | E29: =IF(INVENTARIO!B7="","",INVENTARIO!L7) | F29: =IF(INVENTARIO!B7="","",IF(INVENTARIO!N7="","Definir",INVENTARIO!N7)) | G29: =IF(INVENTARIO!R7="","",INVENTARIO!R7) | H29: =IF(INVENTARIO!S7="","",INVENTARIO!S7) | I29: =IF(INVENTARIO!B7="","",INVENTARIO!M7) | J29: =IF(INVENTARIO!B7="","",INVENTARIO!G7) | K29: =IF(INVENTARIO!B7="","",INVENTARIO!V7) | L29: =IF(INVENTARIO!B7="","",INVENTARIO!J7)
B30: =IF(INVENTARIO!B8="","",INVENTARIO!C8) | D30: =IF(INVENTARIO!B8="","",INVENTARIO!H8) | E30: =IF(INVENTARIO!B8="","",INVENTARIO!L8) | F30: =IF(INVENTARIO!B8="","",IF(INVENTARIO!N8="","Definir",INVENTARIO!N8)) | G30: =IF(INVENTARIO!R8="","",INVENTARIO!R8) | H30: =IF(INVENTARIO!S8="","",INVENTARIO!S8) | I30: =IF(INVENTARIO!B8="","",INVENTARIO!M8) | J30: =IF(INVENTARIO!B8="","",INVENTARIO!G8) | K30: =IF(INVENTARIO!B8="","",INVENTARIO!V8) | L30: =IF(INVENTARIO!B8="","",INVENTARIO!J8)
B31: =IF(INVENTARIO!B9="","",INVENTARIO!C9) | D31: =IF(INVENTARIO!B9="","",INVENTARIO!H9) | E31: =IF(INVENTARIO!B9="","",INVENTARIO!L9) | F31: =IF(INVENTARIO!B9="","",IF(INVENTARIO!N9="","Definir",INVENTARIO!N9)) | G31: =IF(INVENTARIO!R9="","",INVENTARIO!R9) | H31: =IF(INVENTARIO!S9="","",INVENTARIO!S9) | I31: =IF(INVENTARIO!B9="","",INVENTARIO!M9) | J31: =IF(INVENTARIO!B9="","",INVENTARIO!G9) | K31: =IF(INVENTARIO!B9="","",INVENTARIO!V9) | L31: =IF(INVENTARIO!B9="","",INVENTARIO!J9)
B32: =IF(INVENTARIO!B10="","",INVENTARIO!C10) | D32: =IF(INVENTARIO!B10="","",INVENTARIO!H10) | E32: =IF(INVENTARIO!B10="","",INVENTARIO!L10) | F32: =IF(INVENTARIO!B10="","",IF(INVENTARIO!N10="","Definir",INVENTARIO!N10)) | G32: =IF(INVENTARIO!R10="","",INVENTARIO!R10) | H32: =IF(INVENTARIO!S10="","",INVENTARIO!S10) | I32: =IF(INVENTARIO!B10="","",INVENTARIO!M10) | J32: =IF(INVENTARIO!B10="","",INVENTARIO!G10) | K32: =IF(INVENTARIO!B10="","",INVENTARIO!V10) | L32: =IF(INVENTARIO!B10="","",INVENTARIO!J10)
B33: =IF(INVENTARIO!B11="","",INVENTARIO!C11) | D33: =IF(INVENTARIO!B11="","",INVENTARIO!H11) | E33: =IF(INVENTARIO!B11="","",INVENTARIO!L11) | F33: =IF(INVENTARIO!B11="","",IF(INVENTARIO!N11="","Definir",INVENTARIO!N11)) | G33: =IF(INVENTARIO!R11="","",INVENTARIO!R11) | H33: =IF(INVENTARIO!S11="","",INVENTARIO!S11) | I33: =IF(INVENTARIO!B11="","",INVENTARIO!M11) | J33: =IF(INVENTARIO!B11="","",INVENTARIO!G11) | K33: =IF(INVENTARIO!B11="","",INVENTARIO!V11) | L33: =IF(INVENTARIO!B11="","",INVENTARIO!J11)
B34: =IF(INVENTARIO!B12="","",INVENTARIO!C12) | D34: =IF(INVENTARIO!B12="","",INVENTARIO!H12) | E34: =IF(INVENTARIO!B12="","",INVENTARIO!L12) | F34: =IF(INVENTARIO!B12="","",IF(INVENTARIO!N12="","Definir",INVENTARIO!N12)) | G34: =IF(INVENTARIO!R12="","",INVENTARIO!R12) | H34: =IF(INVENTARIO!S12="","",INVENTARIO!S12) | I34: =IF(INVENTARIO!B12="","",INVENTARIO!M12) | J34: =IF(INVENTARIO!B12="","",INVENTARIO!G12) | K34: =IF(INVENTARIO!B12="","",INVENTARIO!V12) | L34: =IF(INVENTARIO!B12="","",INVENTARIO!J12)
B35: =IF(INVENTARIO!B13="","",INVENTARIO!C13) | D35: =IF(INVENTARIO!B13="","",INVENTARIO!H13) | E35: =IF(INVENTARIO!B13="","",INVENTARIO!L13) | F35: =IF(INVENTARIO!B13="","",IF(INVENTARIO!N13="","Definir",INVENTARIO!N13)) | G35: =IF(INVENTARIO!R13="","",INVENTARIO!R13) | H35: =IF(INVENTARIO!S13="","",INVENTARIO!S13) | I35: =IF(INVENTARIO!B13="","",INVENTARIO!M13) | J35: =IF(INVENTARIO!B13="","",INVENTARIO!G13) | K35: =IF(INVENTARIO!B13="","",INVENTARIO!V13) | L35: =IF(INVENTARIO!B13="","",INVENTARIO!J13)
B36: =IF(INVENTARIO!B14="","",INVENTARIO!C14) | D36: =IF(INVENTARIO!B14="","",INVENTARIO!H14) | E36: =IF(INVENTARIO!B14="","",INVENTARIO!L14) | F36: =IF(INVENTARIO!B14="","",IF(INVENTARIO!N14="","Definir",INVENTARIO!N14)) | G36: =IF(INVENTARIO!R14="","",INVENTARIO!R14) | H36: =IF(INVENTARIO!S14="","",INVENTARIO!S14) | I36: =IF(INVENTARIO!B14="","",INVENTARIO!M14) | J36: =IF(INVENTARIO!B14="","",INVENTARIO!G14) | K36: =IF(INVENTARIO!B14="","",INVENTARIO!V14) | L36: =IF(INVENTARIO!B14="","",INVENTARIO!J14)
B37: TOTAL | D37: =INVENTARIO!H27 | I37: =INVENTARIO!M27 | J37: =INVENTARIO!G27
B38: Muestra los primeros 8 productos del catálogo. Detalle completo en la hoja INVENTARIO.
B40: GASTOS POR CATEGORÍA (acumulado) | I40: RESUMEN MENSUAL DEL AÑO
B41: Publicidad (Walmart Sponsored) | F41: =SUMIFS(GASTOS!$J$6:$J$305,GASTOS!$C$6:$C$305,B41) | G41: =IF(SUM($F$41:$F$50)>0,F41/SUM($F$41:$F$50),0) | I41: Mes | J41: Ventas brutas | K41: Ingreso neto | L41: Utilidad neta
B42: Envíos y logística | F42: =SUMIFS(GASTOS!$J$6:$J$305,GASTOS!$C$6:$C$305,B42) | G42: =IF(SUM($F$41:$F$50)>0,F42/SUM($F$41:$F$50),0) | I42: ENE | J42: =ESTADO_RESULTADOS!C8 | K42: =ESTADO_RESULTADOS!C11 | L42: =ESTADO_RESULTADOS!C29
B43: Fulfillment / WFS | F43: =SUMIFS(GASTOS!$J$6:$J$305,GASTOS!$C$6:$C$305,B43) | G43: =IF(SUM($F$41:$F$50)>0,F43/SUM($F$41:$F$50),0) | I43: FEB | J43: =ESTADO_RESULTADOS!D8 | K43: =ESTADO_RESULTADOS!D11 | L43: =ESTADO_RESULTADOS!D29
B44: Empaque y suministros | F44: =SUMIFS(GASTOS!$J$6:$J$305,GASTOS!$C$6:$C$305,B44) | G44: =IF(SUM($F$41:$F$50)>0,F44/SUM($F$41:$F$50),0) | I44: MAR | J44: =ESTADO_RESULTADOS!E8 | K44: =ESTADO_RESULTADOS!E11 | L44: =ESTADO_RESULTADOS!E29
B45: Devoluciones y reembolsos | F45: =SUMIFS(GASTOS!$J$6:$J$305,GASTOS!$C$6:$C$305,B45) | G45: =IF(SUM($F$41:$F$50)>0,F45/SUM($F$41:$F$50),0) | I45: ABR | J45: =ESTADO_RESULTADOS!F8 | K45: =ESTADO_RESULTADOS!F11 | L45: =ESTADO_RESULTADOS!F29
B46: Software y suscripciones | F46: =SUMIFS(GASTOS!$J$6:$J$305,GASTOS!$C$6:$C$305,B46) | G46: =IF(SUM($F$41:$F$50)>0,F46/SUM($F$41:$F$50),0) | I46: MAY | J46: =ESTADO_RESULTADOS!G8 | K46: =ESTADO_RESULTADOS!G11 | L46: =ESTADO_RESULTADOS!G29
B47: Comisiones bancarias | F47: =SUMIFS(GASTOS!$J$6:$J$305,GASTOS!$C$6:$C$305,B47) | G47: =IF(SUM($F$41:$F$50)>0,F47/SUM($F$41:$F$50),0) | I47: JUN | J47: =ESTADO_RESULTADOS!H8 | K47: =ESTADO_RESULTADOS!H11 | L47: =ESTADO_RESULTADOS!H29
...

Sheet GUIA
B1: COTIMIX · GUÍA DE USO DEL SISTEMA
B2: Cómo registrar la operación diaria y leer los reportes.
B6: CÓDIGO DE COLORES
B7: Celda amarilla, texto azul | C7: Dato que USTED captura o puede modificar (inputs).
B8: Celda blanca, texto negro | C8: Fórmula automática. No la sobrescriba.
B9: Texto verde | C9: Vínculo a otra hoja (por ejemplo, el capital en BANCO viene de CONFIG).
B10: Rojo claro | C10: Alerta: dato pendiente (precio sin definir) o resultado negativo.
B12: FLUJO DE TRABAJO
B13: 1. CONFIG | C13: Revise parámetros: capital, reserva, recargo Citi (2.9%), comisión Walmart y margen objetivo.
B14: 2. INVENTARIO | C14: Defina el PRECIO DE VENTA de cada producto (columna N). Ajuste la comisión Walmart de su categoría y el costo de envío por unidad. Para un producto nuevo, agregue un ID (P003, P004...) en una fila vacía.
B15: 3. COMPRAS | C15: Registre cada compra de mercancía. Si elige 'Tarjeta Citi', el 2.9% se suma al costo real automáticamente y la deuda Citi aumenta. El costo unitario del inventario es el promedio ponderado del costo real.
B16: 4. VENTAS | C16: Una fila por orden/producto: fecha, # orden, ID y cantidad. El precio es opcional (si lo deja vacío usa el del catálogo).
B17: 5. GASTOS | C17: Publicidad, envíos, empaques, etc. Use 'Descontado por Walmart' para cargos que Walmart resta de la liquidación.
B18: 6. WALMART | C18: Registre los depósitos que Walmart envía a su banco y los movimientos de la reserva (retenciones y liberaciones).
B19: 7. BANCO | C19: Registre aportes adicionales, retiros del propietario, pagos a la tarjeta Citi y otros ingresos.
B20: 8. Reportes | C20: DASHBOARD, ESTADO_RESULTADOS y BALANCE se actualizan solos. Verifique que el BALANCE diga '✔ CUADRA'.
B22: EJEMPLO DE CAPTURA (VENTAS)
B23: Formato de una fila | C23: Fecha: 05/11/2026 · # Orden: 1089456123 · ID: P002 · Cantidad: 2 · Precio unitario: 79.99 · Envío/otros cargos: 0 → Venta bruta $159.98, comisión 15% $24.00, costo real $86.44, utilidad $49.54.
B25: SUPUESTOS DOCUMENTADOS
B26: Reserva Walmart | C26: $1,190.60 es dinero de COTIMIX retenido por Walmart: se muestra como activo RESTRINGIDO, separado del efectivo.
B27: Origen de la reserva | C27: Se asume que proviene de ventas previas a la apertura → 'Resultados acumulados de apertura' en el patrimonio. Editable en CONFIG.
B28: Deuda Citi | C28: Se asume que la compra de mouse ($1,728.72) aún no se ha pagado: aparece como pasivo hasta registrar el pago en BANCO.
B29: Efectivo inicial | C29: Capital $5,000 − cafeteras pagadas en efectivo $2,070 = $2,930 disponibles a la apertura.
B30: Comisión Walmart | C30: 15% por defecto (tarifa referencial estándar). Verifique la de cada categoría en Seller Center.

Sheet CONFIG
B1: COTIMIX · PARÁMETROS DEL SISTEMA
B2: Supuestos generales y listas maestras. Celdas amarillas = editables.
B5: PARÁMETROS GENERALES | F5: LISTAS MAESTRAS (alimentan los menús desplegables)
B6: Parámetro | C6: Valor | D6: Nota / Fuente | F6: Métodos de pago · Compras | G6: Métodos de pago · Gastos | H6: Categorías de gasto | I6: Tipos de movimiento · Walmart | J6: Tipos de movimiento · Banco
B7: Nombre del negocio | C7: COTIMIX | D7: Dato del propietario. | F7: Efectivo/Banco | G7: Efectivo/Banco | H7: Publicidad (Walmart Sponsored) | I7: Retención a reserva | J7: Aporte de capital
B8: Canal de venta | C8: Walmart Marketplace | D8: Dato del propietario. | F8: Tarjeta Citi | G8: Tarjeta Citi | H8: Envíos y logística | I8: Liberación de reserva | J8: Retiro del propietario
B9: Moneda | C9: USD | D9: Todas las cifras en dólares estadounidenses. | G9: Descontado por Walmart | H9: Fulfillment / WFS | I9: Depósito a banco | J9: Pago tarjeta Citi
B10: Fecha de apertura del sistema | C10: 46323 | D10: Fecha de corte de los saldos iniciales. | H10: Empaque y suministros | J10: Otro ingreso
B11: Año del Estado de Resultados | C11: 2026 | D11: Cambie el año para ver otro ejercicio en ESTADO_RESULTADOS. | H11: Devoluciones y reembolsos
B12: Capital inicial invertido | C12: 5000 | D12: Dato del propietario. Se registra automáticamente en BANCO como aporte. | H12: Software y suscripciones
B13: Reserva Walmart al inicio | C13: 1190.6 | D13: Dato del propietario: dinero de COTIMIX retenido por Walmart, aún no disponible. | H13: Comisiones bancarias
B14: Resultados acumulados de apertura | C14: 1190.6 | D14: SUPUESTO: la reserva de Walmart proviene de ventas anteriores a la apertura del sistema, por lo que se reconoce como utilidad acumulada. Si tuvo otro origen, ajuste este valor; el control de cuadre del BALANCE le indicará cualquier diferencia. | H14: Servicios profesionales
B15: Recargo por pago con tarjeta Citi | C15: 0.029 | D15: Dato del propietario: 2.9% que se suma al costo de toda compra o gasto pagado con Citi. | H15: Impuestos y licencias
B16: Comisión Walmart por defecto (referral fee) | C16: 0.15 | D16: SUPUESTO: 15% es la tarifa estándar de Walmart Marketplace para la mayoría de categorías. Verifique la tarifa de cada categoría en Seller Center y ajústela por producto en INVENTARIO. | H16: Otros gastos
B17: Margen neto objetivo por producto | C17: 0.25 | D17: Se usa para calcular el precio sugerido en INVENTARIO.

Sheet INVENTARIO
B1: COTIMIX · INVENTARIO Y RENTABILIDAD POR PRODUCTO
B2: Stock y costo real se calculan desde COMPRAS y VENTAS. Capture el precio de venta en la columna amarilla.
B5: CATÁLOGO Y EXISTENCIAS | J5: COSTO REAL (incluye recargo Citi) | N5: PRECIO Y RENTABILIDAD UNITARIA
B6: ID | C6: Producto | D6: Categoría | E6: SKU Walmart | F6: Unidades compradas | G6: Unidades vendidas | H6: STOCK ACTUAL | I6: Stock mínimo | J6: Estado | K6: Costo real total | L6: Costo real unitario | M6: VALOR INVENTARIO | N6: PRECIO DE VENTA | O6: Comisión Walmart % | P6: Comisión Walmart $ | Q6: Envío / fulfillment por unidad | R6: UTILIDAD POR UNIDAD | S6: Margen neto % | T6: ROI por unidad % | U6: Precio mínimo (break-even) | V6: Precio sugerido (margen obj.) | W6: Utilidad potencial del stock
B7: P001 | C7: Cafeteras | D7: Hogar / Cocina | F7: =IF($B7="","",SUMIFS(COMPRAS!$F$6:$F$305,COMPRAS!$C$6:$C$305,$B7)) | G7: =IF($B7="","",SUMIFS(VENTAS!$F$6:$F$505,VENTAS!$D$6:$D$505,$B7)) | H7: =IF($B7="","",F7-G7) | I7: 5 | J7: =IF($B7="","",IF(H7<=0,"AGOTADO",IF(H7<=N(I7),"REORDENAR","OK"))) | K7: =IF($B7="","",SUMIFS(COMPRAS!$L$6:$L$305,COMPRAS!$C$6:$C$305,$B7)) | L7: =IF($B7="","",IF(F7>0,K7/F7,0)) | M7: =IF($B7="","",H7*L7) | O7: 0.15 | P7: =IF(OR($B7="",$N7=""),"",N7*O7) | Q7: 0 | R7: =IF(OR($B7="",$N7=""),"",N7-P7-Q7-L7) | S7: =IF(OR($B7="",$N7=""),"",IF(N7>0,R7/N7,0)) | T7: =IF(OR($B7="",$N7=""),"",IF(L7>0,R7/L7,0)) | U7: =IF($B7="","",IF(O7<1,(L7+Q7)/(1-O7),0)) | V7: =IF($B7="","",IF(O7+CFG_MARGEN<1,(L7+Q7)/(1-O7-CFG_MARGEN),0)) | W7: =IF(OR($B7="",$N7=""),"",R7*H7)
B8: P002 | C8: Mouse Logitech | D8: Electrónica | F8: =IF($B8="","",SUMIFS(COMPRAS!$F$6:$F$305,COMPRAS!$C$6:$C$305,$B8)) | G8: =IF($B8="","",SUMIFS(VENTAS!$F$6:$F$505,VENTAS!$D$6:$D$505,$B8)) | H8: =IF($B8="","",F8-G8) | I8: 8 | J8: =IF($B8="","",IF(H8<=0,"AGOTADO",IF(H8<=N(I8),"REORDENAR","OK"))) | K8: =IF($B8="","",SUMIFS(COMPRAS!$L$6:$L$305,COMPRAS!$C$6:$C$305,$B8)) | L8: =IF($B8="","",IF(F8>0,K8/F8,0)) | M8: =IF($B8="","",H8*L8) | O8: 0.15 | P8: =IF(OR($B8="",$N8=""),"",N8*O8) | Q8: 0 | R8: =IF(OR($B8="",$N8=""),"",N8-P8-Q8-L8) | S8: =IF(OR($B8="",$N8=""),"",IF(N8>0,R8/N8,0)) | T8: =IF(OR($B8="",$N8=""),"",IF(L8>0,R8/L8,0)) | U8: =IF($B8="","",IF(O8<1,(L8+Q8)/(1-O8),0)) | V8: =IF($B8="","",IF(O8+CFG_MARGEN<1,(L8+Q8)/(1-O8-CFG_MARGEN),0)) | W8: =IF(OR($B8="",$N8=""),"",R8*H8)
F9: =IF($B9="","",SUMIFS(COMPRAS!$F$6:$F$305,COMPRAS!$C$6:$C$305,$B9)) | G9: =IF($B9="","",SUMIFS(VENTAS!$F$6:$F$505,VENTAS!$D$6:$D$505,$B9)) | H9: =IF($B9="","",F9-G9) | J9: =IF($B9="","",IF(H9<=0,"AGOTADO",IF(H9<=N(I9),"REORDENAR","OK"))) | K9: =IF($B9="","",SUMIFS(COMPRAS!$L$6:$L$305,COMPRAS!$C$6:$C$305,$B9)) | L9: =IF($B9="","",IF(F9>0,K9/F9,0)) | M9: =IF($B9="","",H9*L9) | P9: =IF(OR($B9="",$N9=""),"",N9*O9) | R9: =IF(OR($B9="",$N9=""),"",N9-P9-Q9-L9) | S9: =IF(OR($B9="",$N9=""),"",IF(N9>0,R9/N9,0)) | T9: =IF(OR($B9="",$N9=""),"",IF(L9>0,R9/L9,0)) | U9: =IF($B9="","",IF(O9<1,(L9+Q9)/(1-O9),0)) | V9: =IF($B9="","",IF(O9+CFG_MARGEN<1,(L9+Q9)/(1-O9-CFG_MARGEN),0)) | W9: =IF(OR($B9="",$N9=""),"",R9*H9)
F10: =IF($B10="","",SUMIFS(COMPRAS!$F$6:$F$305,COMPRAS!$C$6:$C$305,$B10)) | G10: =IF($B10="","",SUMIFS(VENTAS!$F$6:$F$505,VENTAS!$D$6:$D$505,$B10)) | H10: =IF($B10="","",F10-G10) | J10: =IF($B10="","",IF(H10<=0,"AGOTADO",IF(H10<=N(I10),"REORDENAR","OK"))) | K10: =IF($B10="","",SUMIFS(COMPRAS!$L$6:$L$305,COMPRAS!$C$6:$C$305,$B10)) | L10: =IF($B10="","",IF(F10>0,K10/F10,0)) | M10: =IF($B10="","",H10*L10) | P10: =IF(OR($B10="",$N10=""),"",N10*O10) | R10: =IF(OR($B10="",$N10=""),"",N10-P10-Q10-L10) | S10: =IF(OR($B10="",$N10=""),"",IF(N10>0,R10/N10,0)) | T10: =IF(OR($B10="",$N10=""),"",IF(L10>0,R10/L10,0)) | U10: =IF($B10="","",IF(O10<1,(L10+Q10)/(1-O10),0)) | V10: =IF($B10="","",IF(O10+CFG_MARGEN<1,(L10+Q10)/(1-O10-CFG_MARGEN),0)) | W10: =IF(OR($B10="",$N10=""),"",R10*H10)
F11: =IF($B11="","",SUMIFS(COMPRAS!$F$6:$F$305,COMPRAS!$C$6:$C$305,$B11)) | G11: =IF($B11="","",SUMIFS(VENTAS!$F$6:$F$505,VENTAS!$D$6:$D$505,$B11)) | H11: =IF($B11="","",F11-G11) | J11: =IF($B11="","",IF(H11<=0,"AGOTADO",IF(H11<=N(I11),"REORDENAR","OK"))) | K11: =IF($B11="","",SUMIFS(COMPRAS!$L$6:$L$305,COMPRAS!$C$6:$C$305,$B11)) | L11: =IF($B11="","",IF(F11>0,K11/F11,0)) | M11: =IF($B11="","",H11*L11) | P11: =IF(OR($B11="",$N11=""),"",N11*O11) | R11: =IF(OR($B11="",$N11=""),"",N11-P11-Q11-L11) | S11: =IF(OR($B11="",$N11=""),"",IF(N11>0,R11/N11,0)) | T11: =IF(OR($B11="",$N11=""),"",IF(L11>0,R11/L11,0)) | U11: =IF($B11="","",IF(O11<1,(L11+Q11)/(1-O11),0)) | V11: =IF($B11="","",IF(O11+CFG_MARGEN<1,(L11+Q11)/(1-O11-CFG_MARGEN),0)) | W11: =IF(OR($B11="",$N11=""),"",R11*H11)
F12: =IF($B12="","",SUMIFS(COMPRAS!$F$6:$F$305,COMPRAS!$C$6:$C$305,$B12)) | G12: =IF($B12="","",SUMIFS(VENTAS!$F$6:$F$505,VENTAS!$D$6:$D$505,$B12)) | H12: =IF($B12="","",F12-G12) | J12: =IF($B12="","",IF(H12<=0,"AGOTADO",IF(H12<=N(I12),"REORDENAR","OK"))) | K12: =IF($B12="","",SUMIFS(COMPRAS!$L$6:$L$305,COMPRAS!$C$6:$C$305,$B12)) | L12: =IF($B12="","",IF(F12>0,K12/F12,0)) | M12: =IF($B12="","",H12*L12) | P12: =IF(OR($B12="",$N12=""),"",N12*O12) | R12: =IF(OR($B12="",$N12=""),"",N12-P12-Q12-L12) | S12: =IF(OR($B12="",$N12=""),"",IF(N12>0,R12/N12,0)) | T12: =IF(OR($B12="",$N12=""),"",IF(L12>0,R12/L12,0)) | U12: =IF($B12="","",IF(O12<1,(L12+Q12)/(1-O12),0)) | V12: =IF($B12="","",IF(O12+CFG_MARGEN<1,(L12+Q12)/(1-O12-CFG_MARGEN),0)) | W12: =IF(OR($B12="",$N12=""),"",R12*H12)
F13: =IF($B13="","",SUMIFS(COMPRAS!$F$6:$F$305,COMPRAS!$C$6:$C$305,$B13)) | G13: =IF($B13="","",SUMIFS(VENTAS!$F$6:$F$505,VENTAS!$D$6:$D$505,$B13)) | H13: =IF($B13="","",F13-G13) | J13: =IF($B13="","",IF(H13<=0,"AGOTADO",IF(H13<=N(I13),"REORDENAR","OK"))) | K13: =IF($B13="","",SUMIFS(COMPRAS!$L$6:$L$305,COMPRAS!$C$6:$C$305,$B13)) | L13: =IF($B13="","",IF(F13>0,K13/F13,0)) | M13: =IF($B13="","",H13*L13) | P13: =IF(OR($B13="",$N13=""),"",N13*O13) | R13: =IF(OR($B13="",$N13=""),"",N13-P13-Q13-L13) | S13: =IF(OR($B13="",$N13=""),"",IF(N13>0,R13/N13,0)) | T13: =IF(OR($B13="",$N13=""),"",IF(L13>0,R13/L13,0)) | U13: =IF($B13="","",IF(O13<1,(L13+Q13)/(1-O13),0)) | V13: =IF($B13="","",IF(O13+CFG_MARGEN<1,(L13+Q13)/(1-O13-CFG_MARGEN),0)) | W13: =IF(OR($B13="",$N13=""),"",R13*H13)
F14: =IF($B14="","",SUMIFS(COMPRAS!$F$6:$F$305,COMPRAS!$C$6:$C$305,$B14)) | G14: =IF($B14="","",SUMIFS(VENTAS!$F$6:$F$505,VENTAS!$D$6:$D$505,$B14)) | H14: =IF($B14="","",F14-G14) | J14: =IF($B14="","",IF(H14<=0,"AGOTADO",IF(H14<=N(I14),"REORDENAR","OK"))) | K14: =IF($B14="","",SUMIFS(COMPRAS!$L$6:$L$305,COMPRAS!$C$6:$C$305,$B14)) | L14: =IF($B14="","",IF(F14>0,K14/F14,0)) | M14: =IF($B14="","",H14*L14) | P14: =IF(OR($B14="",$N14=""),"",N14*O14) | R14: =IF(OR($B14="",$N14=""),"",N14-P14-Q14-L14) | S14: =IF(OR($B14="",$N14=""),"",IF(N14>0,R14/N14,0)) | T14: =IF(OR($B14="",$N14=""),"",IF(L14>0,R14/L14,0)) | U14: =IF($B14="","",IF(O14<1,(L14+Q14)/(1-O14),0)) | V14: =IF($B14="","",IF(O14+CFG_MARGEN<1,(L14+Q14)/(1-O14-CFG_MARGEN),0)) | W14: =IF(OR($B14="",$N14=""),"",R14*H14)
F15: =IF($B15="","",SUMIFS(COMPRAS!$F$6:$F$305,COMPRAS!$C$6:$C$305,$B15)) | G15: =IF($B15="","",SUMIFS(VENTAS!$F$6:$F$505,VENTAS!$D$6:$D$505,$B15)) | H15: =IF($B15="","",F15-G15) | J15: =IF($B15="","",IF(H15<=0,"AGOTADO",IF(H15<=N(I15),"REORDENAR","OK"))) | K15: =IF($B15="","",SUMIFS(COMPRAS!$L$6:$L$305,COMPRAS!$C$6:$C$305,$B15)) | L15: =IF($B15="","",IF(F15>0,K15/F15,0)) | M15: =IF($B15="","",H15*L15) | P15: =IF(OR($B15="",$N15=""),"",N15*O15) | R15: =IF(OR($B15="",$N15=""),"",N15-P15-Q15-L15) | S15: =IF(OR($B15="",$N15=""),"",IF(N15>0,R15/N15,0)) | T15: =IF(OR($B15="",$N15=""),"",IF(L15>0,R15/L15,0)) | U15: =IF($B15="","",IF(O15<1,(L15+Q15)/(1-O15),0)) | V15: =IF($B15="","",IF(O15+CFG_MARGEN<1,(L15+Q15)/(1-O15-CFG_MARGEN),0)) | W15: =IF(OR($B15="",$N15=""),"",R15*H15)
F16: =IF($B16="","",SUMIFS(COMPRAS!$F$6:$F$305,COMPRAS!$C$6:$C$305,$B16)) | G16: =IF($B16="","",SUMIFS(VENTAS!$F$6:$F$505,VENTAS!$D$6:$D$505,$B16)) | H16: =IF($B16="","",F16-G16) | J16: =IF($B16="","",IF(H16<=0,"AGOTADO",IF(H16<=N(I16),"REORDENAR","OK"))) | K16: =IF($B16="","",SUMIFS(COMPRAS!$L$6:$L$305,COMPRAS!$C$6:$C$305,$B16)) | L16: =IF($B16="","",IF(F16>0,K16/F16,0)) | M16: =IF($B16="","",H16*L16) | P16: =IF(OR($B16="",$N16=""),"",N16*O16) | R16: =IF(OR($B16="",$N16=""),"",N16-P16-Q16-L16) | S16: =IF(OR($B16="",$N16=""),"",IF(N16>0,R16/N16,0)) | T16: =IF(OR($B16="",$N16=""),"",IF(L16>0,R16/L16,0)) | U16: =IF($B16="","",IF(O16<1,(L16+Q16)/(1-O16),0)) | V16: =IF($B16="","",IF(O16+CFG_MARGEN<1,(L16+Q16)/(1-O16-CFG_MARGEN),0)) | W16: =IF(OR($B16="",$N16=""),"",R16*H16)
F17: =IF($B17="","",SUMIFS(COMPRAS!$F$6:$F$305,COMPRAS!$C$6:$C$305,$B17)) | G17: =IF($B17="","",SUMIFS(VENTAS!$F$6:$F$505,VENTAS!$D$6:$D$505,$B17)) | H17: =IF($B17="","",F17-G17) | J17: =IF($B17="","",IF(H17<=0,"AGOTADO",IF(H17<=N(I17),"REORDENAR","OK"))) | K17: =IF($B17="","",SUMIFS(COMPRAS!$L$6:$L$305,COMPRAS!$C$6:$C$305,$B17)) | L17: =IF($B17="","",IF(F17>0,K17/F17,0)) | M17: =IF($B17="","",H17*L17) | P17: =IF(OR($B17="",$N17=""),"",N17*O17) | R17: =IF(OR($B17="",$N17=""),"",N17-P17-Q17-L17) | S17: =IF(OR($B17="",$N17=""),"",IF(N17>0,R17/N17,0)) | T17: =IF(OR($B17="",$N17=""),"",IF(L17>0,R17/L17,0)) | U17: =IF($B17="","",IF(O17<1,(L17+Q17)/(1-O17),0)) | V17: =IF($B17="","",IF(O17+CFG_MARGEN<1,(L17+Q17)/(1-O17-CFG_MARGEN),0)) | W17: =IF(OR($B17="",$N17=""),"",R17*H17)
F18: =IF($B18="","",SUMIFS(COMPRAS!$F$6:$F$305,COMPRAS!$C$6:$C$305,$B18)) | G18: =IF($B18="","",SUMIFS(VENTAS!$F$6:$F$505,VENTAS!$D$6:$D$505,$B18)) | H18: =IF($B18="","",F18-G18) | J18: =IF($B18="","",IF(H18<=0,"AGOTADO",IF(H18<=N(I18),"REORDENAR","OK"))) | K18: =IF($B18="","",SUMIFS(COMPRAS!$L$6:$L$305,COMPRAS!$C$6:$C$305,$B18)) | L18: =IF($B18="","",IF(F18>0,K18/F18,0)) | M18: =IF($B18="","",H18*L18) | P18: =IF(OR($B18="",$N18=""),"",N18*O18) | R18: =IF(OR($B18="",$N18=""),"",N18-P18-Q18-L18) | S18: =IF(OR($B18="",$N18=""),"",IF(N18>0,R18/N18,0)) | T18: =IF(OR($B18="",$N18=""),"",IF(L18>0,R18/L18,0)) | U18: =IF($B18="","",IF(O18<1,(L18+Q18)/(1-O18),0)) | V18: =IF($B18="","",IF(O18+CFG_MARGEN<1,(L18+Q18)/(1-O18-CFG_MARGEN),0)) | W18: =IF(OR($B18="",$N18=""),"",R18*H18)
F19: =IF($B19="","",SUMIFS(COMPRAS!$F$6:$F$305,COMPRAS!$C$6:$C$305,$B19)) | G19: =IF($B19="","",SUMIFS(VENTAS!$F$6:$F$505,VENTAS!$D$6:$D$505,$B19)) | H19: =IF($B19="","",F19-G19) | J19: =IF($B19="","",IF(H19<=0,"AGOTADO",IF(H19<=N(I19),"REORDENAR","OK"))) | K19: =IF($B19="","",SUMIFS(COMPRAS!$L$6:$L$305,COMPRAS!$C$6:$C$305,$B19)) | L19: =IF($B19="","",IF(F19>0,K19/F19,0)) | M19: =IF($B19="","",H19*L19) | P19: =IF(OR($B19="",$N19=""),"",N19*O19) | R19: =IF(OR($B19="",$N19=""),"",N19-P19-Q19-L19) | S19: =IF(OR($B19="",$N19=""),"",IF(N19>0,R19/N19,0)) | T19: =IF(OR($B19="",$N19=""),"",IF(L19>0,R19/L19,0)) | U19: =IF($B19="","",IF(O19<1,(L19+Q19)/(1-O19),0)) | V19: =IF($B19="","",IF(O19+CFG_MARGEN<1,(L19+Q19)/(1-O19-CFG_MARGEN),0)) | W19: =IF(OR($B19="",$N19=""),"",R19*H19)
F20: =IF($B20="","",SUMIFS(COMPRAS!$F$6:$F$305,COMPRAS!$C$6:$C$305,$B20)) | G20: =IF($B20="","",SUMIFS(VENTAS!$F$6:$F$505,VENTAS!$D$6:$D$505,$B20)) | H20: =IF($B20="","",F20-G20) | J20: =IF($B20="","",IF(H20<=0,"AGOTADO",IF(H20<=N(I20),"REORDENAR","OK"))) | K20: =IF($B20="","",SUMIFS(COMPRAS!$L$6:$L$305,COMPRAS!$C$6:$C$305,$B20)) | L20: =IF($B20="","",IF(F20>0,K20/F20,0)) | M20: =IF($B20="","",H20*L20) | P20: =IF(OR($B20="",$N20=""),"",N20*O20) | R20: =IF(OR($B20="",$N20=""),"",N20-P20-Q20-L20) | S20: =IF(OR($B20="",$N20=""),"",IF(N20>0,R20/N20,0)) | T20: =IF(OR($B20="",$N20=""),"",IF(L20>0,R20/L20,0)) | U20: =IF($B20="","",IF(O20<1,(L20+Q20)/(1-O20),0)) | V20: =IF($B20="","",IF(O20+CFG_MARGEN<1,(L20+Q20)/(1-O20-CFG_MARGEN),0)) | W20: =IF(OR($B20="",$N20=""),"",R20*H20)
... F26: =IF($B26="","",SUMIFS(COMPRAS!$F$6:$F$305,COMPRAS!$C$6:$C$305,$B26)) | G26: =IF($B26="","",SUMIFS(VENTAS!$F$6:$F$505,VENTAS!$D$6:$D$505,$B26)) | H26: =IF($B26="","",F26-G26) | J26: =IF($B26="","",IF(H26<=0,"AGOTADO",IF(H26<=N(I26),"REORDENAR","OK"))) | K26: =IF($B26="","",SUMIFS(COMPRAS!$L$6:$L$305,COMPRAS!$C$6:$C$305,$B26)) | L26: =IF($B26="","",IF(F26>0,K26/F26,0)) | M26: =IF($B26="","",H26*L26) | P26: =IF(OR($B26="",$N26=""),"",N26*O26) | R26: =IF(OR($B26="",$N26=""),"",N26-P26-Q26-L26) | S26: =IF(OR($B26="",$N26=""),"",IF(N26>0,R26/N26,0)) | T26: =IF(OR($B26="",$N26=""),"",IF(L26>0,R26/L26,0)) | U26: =IF($B26="","",IF(O26<1,(L26+Q26)/(1-O26),0)) | V26: =IF($B26="","",IF(O26+CFG_MARGEN<1,(L26+Q26)/(1-O26-CFG_MARGEN),0)) | W26: =IF(OR($B26="",$N26=""),"",R26*H26)
B27: TOTAL | F27: =SUM(F7:F26) | G27: =SUM(G7:G26) | H27: =SUM(H7:H26) | K27: =SUM(K7:K26) | M27: =SUM(M7:M26) | W27: =SUM(W7:W26)
B29: Leyenda: | C29: Amarillo = dato editable · Blanco = cálculo automático · Precio en rojo claro = precio pendiente de definir · Margen en rojo = por debajo del objetivo (CONFIG).

Sheet COMPRAS
B1: COTIMIX · REGISTRO DE COMPRAS DE INVENTARIO
B2: Cada compra suma unidades y costo al inventario. Si se paga con Citi, el 2.9% se integra al costo del producto.
B4: Columnas amarillas = captura · blancas = automáticas
B5: Fecha | C5: ID Producto | D5: Producto | E5: Proveedor | F5: Cantidad | G5: Costo unitario (factura) | H5: Subtotal | I5: Método de pago | J5: Recargo tarjeta % | K5: Recargo tarjeta $ | L5: COSTO REAL TOTAL | M5: Costo real por unidad | N5: Notas
B6: 46323 | C6: P001 | D6: =IF($C6="","",IFERROR(INDEX(INVENTARIO!$C$7:$C$26,MATCH($C6,INVENTARIO!$B$7:$B$26,0)),"⚠ ID no existe")) | E6: Proveedor cafeteras | F6: 23 | G6: 90 | H6: =IF($C6="","",$F6*$G6) | I6: Efectivo/Banco | J6: =IF($C6="","",IF($I6="Tarjeta Citi",CFG_CITI,0)) | K6: =IF($C6="","",$H6*$J6) | L6: =IF($C6="","",$H6+$K6) | M6: =IF(OR($C6="",N($F6)=0),"",$L6/$F6) | N6: Compra inicial pagada en efectivo, sin recargo.
B7: 46323 | C7: P002 | D7: =IF($C7="","",IFERROR(INDEX(INVENTARIO!$C$7:$C$26,MATCH($C7,INVENTARIO!$B$7:$B$26,0)),"⚠ ID no existe")) | E7: Proveedor Logitech | F7: 40 | G7: 42 | H7: =IF($C7="","",$F7*$G7) | I7: Tarjeta Citi | J7: =IF($C7="","",IF($I7="Tarjeta Citi",CFG_CITI,0)) | K7: =IF($C7="","",$H7*$J7) | L7: =IF($C7="","",$H7+$K7) | M7: =IF(OR($C7="",N($F7)=0),"",$L7/$F7) | N7: Compra inicial con Citi: 2.9% integrado al costo ($48.72).
D8: =IF($C8="","",IFERROR(INDEX(INVENTARIO!$C$7:$C$26,MATCH($C8,INVENTARIO!$B$7:$B$26,0)),"⚠ ID no existe")) | H8: =IF($C8="","",$F8*$G8) | J8: =IF($C8="","",IF($I8="Tarjeta Citi",CFG_CITI,0)) | K8: =IF($C8="","",$H8*$J8) | L8: =IF($C8="","",$H8+$K8) | M8: =IF(OR($C8="",N($F8)=0),"",$L8/$F8)
D9: =IF($C9="","",IFERROR(INDEX(INVENTARIO!$C$7:$C$26,MATCH($C9,INVENTARIO!$B$7:$B$26,0)),"⚠ ID no existe")) | H9: =IF($C9="","",$F9*$G9) | J9: =IF($C9="","",IF($I9="Tarjeta Citi",CFG_CITI,0)) | K9: =IF($C9="","",$H9*$J9) | L9: =IF($C9="","",$H9+$K9) | M9: =IF(OR($C9="",N($F9)=0),"",$L9/$F9)
D10: =IF($C10="","",IFERROR(INDEX(INVENTARIO!$C$7:$C$26,MATCH($C10,INVENTARIO!$B$7:$B$26,0)),"⚠ ID no existe")) | H10: =IF($C10="","",$F10*$G10) | J10: =IF($C10="","",IF($I10="Tarjeta Citi",CFG_CITI,0)) | K10: =IF($C10="","",$H10*$J10) | L10: =IF($C10="","",$H10+$K10) | M10: =IF(OR($C10="",N($F10)=0),"",$L10/$F10)
D11: =IF($C11="","",IFERROR(INDEX(INVENTARIO!$C$7:$C$26,MATCH($C11,INVENTARIO!$B$7:$B$26,0)),"⚠ ID no existe")) | H11: =IF($C11="","",$F11*$G11) | J11: =IF($C11="","",IF($I11="Tarjeta Citi",CFG_CITI,0)) | K11: =IF($C11="","",$H11*$J11) | L11: =IF($C11="","",$H11+$K11) | M11: =IF(OR($C11="",N($F11)=0),"",$L11/$F11)
D12: =IF($C12="","",IFERROR(INDEX(INVENTARIO!$C$7:$C$26,MATCH($C12,INVENTARIO!$B$7:$B$26,0)),"⚠ ID no existe")) | H12: =IF($C12="","",$F12*$G12) | J12: =IF($C12="","",IF($I12="Tarjeta Citi",CFG_CITI,0)) | K12: =IF($C12="","",$H12*$J12) | L12: =IF($C12="","",$H12+$K12) | M12: =IF(OR($C12="",N($F12)=0),"",$L12/$F12)
D13: =IF($C13="","",IFERROR(INDEX(INVENTARIO!$C$7:$C$26,MATCH($C13,INVENTARIO!$B$7:$B$26,0)),"⚠ ID no existe")) | H13: =IF($C13="","",$F13*$G13) | J13: =IF($C13="","",IF($I13="Tarjeta Citi",CFG_CITI,0)) | K13: =IF($C13="","",$H13*$J13) | L13: =IF($C13="","",$H13+$K13) | M13: =IF(OR($C13="",N($F13)=0),"",$L13/$F13)
D14: =IF($C14="","",IFERROR(INDEX(INVENTARIO!$C$7:$C$26,MATCH($C14,INVENTARIO!$B$7:$B$26,0)),"⚠ ID no existe")) | H14: =IF($C14="","",$F14*$G14) | J14: =IF($C14="","",IF($I14="Tarjeta Citi",CFG_CITI,0)) | K14: =IF($C14="","",$H14*$J14) | L14: =IF($C14="","",$H14+$K14) | M14: =IF(OR($C14="",N($F14)=0),"",$L14/$F14)
D15: =IF($C15="","",IFERROR(INDEX(INVENTARIO!$C$7:$C$26,MATCH($C15,INVENTARIO!$B$7:$B$26,0)),"⚠ ID no existe")) | H15: =IF($C15="","",$F15*$G15) | J15: =IF($C15="","",IF($I15="Tarjeta Citi",CFG_CITI,0)) | K15: =IF($C15="","",$H15*$J15) | L15: =IF($C15="","",$H15+$K15) | M15: =IF(OR($C15="",N($F15)=0),"",$L15/$F15)
D16: =IF($C16="","",IFERROR(INDEX(INVENTARIO!$C$7:$C$26,MATCH($C16,INVENTARIO!$B$7:$B$26,0)),"⚠ ID no existe")) | H16: =IF($C16="","",$F16*$G16) | J16: =IF($C16="","",IF($I16="Tarjeta Citi",CFG_CITI,0)) | K16: =IF($C16="","",$H16*$J16) | L16: =IF($C16="","",$H16+$K16) | M16: =IF(OR($C16="",N($F16)=0),"",$L16/$F16)
D17: =IF($C17="","",IFERROR(INDEX(INVENTARIO!$C$7:$C$26,MATCH($C17,INVENTARIO!$B$7:$B$26,0)),"⚠ ID no existe")) | H17: =IF($C17="","",$F17*$G17) | J17: =IF($C17="","",IF($I17="Tarjeta Citi",CFG_CITI,0)) | K17: =IF($C17="","",$H17*$J17) | L17: =IF($C17="","",$H17+$K17) | M17: =IF(OR($C17="",N($F17)=0),"",$L17/$F17)
D18: =IF($C18="","",IFERROR(INDEX(INVENTARIO!$C$7:$C$26,MATCH($C18,INVENTARIO!$B$7:$B$26,0)),"⚠ ID no existe")) | H18: =IF($C18="","",$F18*$G18) | J18: =IF($C18="","",IF($I18="Tarjeta Citi",CFG_CITI,0)) | K18: =IF($C18="","",$H18*$J18) | L18: =IF($C18="","",$H18+$K18) | M18: =IF(OR($C18="",N($F18)=0),"",$L18/$F18)
D19: =IF($C19="","",IFERROR(INDEX(INVENTARIO!$C$7:$C$26,MATCH($C19,INVENTARIO!$B$7:$B$26,0)),"⚠ ID no existe")) | H19: =IF($C19="","",$F19*$G19) | J19: =IF($C19="","",IF($I19="Tarjeta Citi",CFG_CITI,0)) | K19: =IF($C19="","",$H19*$J19) | L19: =IF($C19="","",$H19+$K19) | M19: =IF(OR($C19="",N($F19)=0),"",$L19/$F19)
... D305: =IF($C305="","",IFERROR(INDEX(INVENTARIO!$C$7:$C$26,MATCH($C305,INVENTARIO!$B$7:$B$26,0)),"⚠ ID no existe")) | H305: =IF($C305="","",$F305*$G305) | J305: =IF($C305="","",IF($I305="Tarjeta Citi",CFG_CITI,0)) | K305: =IF($C305="","",$H305*$J305) | L305: =IF($C305="","",$H305+$K305) | M305: =IF(OR($C305="",N($F305)=0),"",$L305/$F305)
B306: TOTAL | F306: =SUM(F6:F305) | H306: =SUM(H6:H305) | K306: =SUM(K6:K305) | L306: =SUM(L6:L305)

Sheet VENTAS
B1: COTIMIX · REGISTRO DE VENTAS WALMART MARKETPLACE
B2: Capture fecha, orden, ID, cantidad y (opcional) precio. Comisiones, costo de ventas y utilidad se calculan solos.
B4: Si deja vacío el precio unitario se usa el PRECIO DE VENTA del catálogo (INVENTARIO).
B5: Fecha | C5: # Orden Walmart | D5: ID Producto | E5: Producto | F5: Cantidad | G5: Precio unitario (opcional) | H5: Precio aplicado | I5: VENTA BRUTA | J5: Comisión Walmart % | K5: Comisión Walmart $ | L5: Envío / otros cargos Walmart | M5: INGRESO NETO | N5: Costo real unitario | O5: COSTO DE VENTAS | P5: UTILIDAD BRUTA | Q5: Margen % | R5: Notas
E6: =IF($D6="","",IFERROR(INDEX(INVENTARIO!$C$7:$C$26,MATCH($D6,INVENTARIO!$B$7:$B$26,0)),"⚠ ID no existe")) | H6: =IF($D6="","",IF($G6="",IFERROR(INDEX(INVENTARIO!$N$7:$N$26,MATCH($D6,INVENTARIO!$B$7:$B$26,0)),""),$G6)) | I6: =IF($D6="","",N($F6)*IF(ISNUMBER($H6),$H6,0)) | J6: =IF($D6="","",IFERROR(IF(INDEX(INVENTARIO!$O$7:$O$26,MATCH($D6,INVENTARIO!$B$7:$B$26,0))="",CFG_WALMART,INDEX(INVENTARIO!$O$7:$O$26,MATCH($D6,INVENTARIO!$B$7:$B$26,0))),CFG_WALMART)) | K6: =IF($D6="","",$I6*$J6) | M6: =IF($D6="","",$I6-$K6-N($L6)) | N6: =IF($D6="","",IFERROR(INDEX(INVENTARIO!$L$7:$L$26,MATCH($D6,INVENTARIO!$B$7:$B$26,0))*1,0)) | O6: =IF($D6="","",N($F6)*$N6) | P6: =IF($D6="","",$M6-$O6) | Q6: =IF($D6="","",IF($I6>0,$P6/$I6,""))
E7: =IF($D7="","",IFERROR(INDEX(INVENTARIO!$C$7:$C$26,MATCH($D7,INVENTARIO!$B$7:$B$26,0)),"⚠ ID no existe")) | H7: =IF($D7="","",IF($G7="",IFERROR(INDEX(INVENTARIO!$N$7:$N$26,MATCH($D7,INVENTARIO!$B$7:$B$26,0)),""),$G7)) | I7: =IF($D7="","",N($F7)*IF(ISNUMBER($H7),$H7,0)) | J7: =IF($D7="","",IFERROR(IF(INDEX(INVENTARIO!$O$7:$O$26,MATCH($D7,INVENTARIO!$B$7:$B$26,0))="",CFG_WALMART,INDEX(INVENTARIO!$O$7:$O$26,MATCH($D7,INVENTARIO!$B$7:$B$26,0))),CFG_WALMART)) | K7: =IF($D7="","",$I7*$J7) | M7: =IF($D7="","",$I7-$K7-N($L7)) | N7: =IF($D7="","",IFERROR(INDEX(INVENTARIO!$L$7:$L$26,MATCH($D7,INVENTARIO!$B$7:$B$26,0))*1,0)) | O7: =IF($D7="","",N($F7)*$N7) | P7: =IF($D7="","",$M7-$O7) | Q7: =IF($D7="","",IF($I7>0,$P7/$I7,""))
E8: =IF($D8="","",IFERROR(INDEX(INVENTARIO!$C$7:$C$26,MATCH($D8,INVENTARIO!$B$7:$B$26,0)),"⚠ ID no existe")) | H8: =IF($D8="","",IF($G8="",IFERROR(INDEX(INVENTARIO!$N$7:$N$26,MATCH($D8,INVENTARIO!$B$7:$B$26,0)),""),$G8)) | I8: =IF($D8="","",N($F8)*IF(ISNUMBER($H8),$H8,0)) | J8: =IF($D8="","",IFERROR(IF(INDEX(INVENTARIO!$O$7:$O$26,MATCH($D8,INVENTARIO!$B$7:$B$26,0))="",CFG_WALMART,INDEX(INVENTARIO!$O$7:$O$26,MATCH($D8,INVENTARIO!$B$7:$B$26,0))),CFG_WALMART)) | K8: =IF($D8="","",$I8*$J8) | M8: =IF($D8="","",$I8-$K8-N($L8)) | N8: =IF($D8="","",IFERROR(INDEX(INVENTARIO!$L$7:$L$26,MATCH($D8,INVENTARIO!$B$7:$B$26,0))*1,0)) | O8: =IF($D8="","",N($F8)*$N8) | P8: =IF($D8="","",$M8-$O8) | Q8: =IF($D8="","",IF($I8>0,$P8/$I8,""))
E9: =IF($D9="","",IFERROR(INDEX(INVENTARIO!$C$7:$C$26,MATCH($D9,INVENTARIO!$B$7:$B$26,0)),"⚠ ID no existe")) | H9: =IF($D9="","",IF($G9="",IFERROR(INDEX(INVENTARIO!$N$7:$N$26,MATCH($D9,INVENTARIO!$B$7:$B$26,0)),""),$G9)) | I9: =IF($D9="","",N($F9)*IF(ISNUMBER($H9),$H9,0)) | J9: =IF($D9="","",IFERROR(IF(INDEX(INVENTARIO!$O$7:$O$26,MATCH($D9,INVENTARIO!$B$7:$B$26,0))="",CFG_WALMART,INDEX(INVENTARIO!$O$7:$O$26,MATCH($D9,INVENTARIO!$B$7:$B$26,0))),CFG_WALMART)) | K9: =IF($D9="","",$I9*$J9) | M9: =IF($D9="","",$I9-$K9-N($L9)) | N9: =IF($D9="","",IFERROR(INDEX(INVENTARIO!$L$7:$L$26,MATCH($D9,INVENTARIO!$B$7:$B$26,0))*1,0)) | O9: =IF($D9="","",N($F9)*$N9) | P9: =IF($D9="","",$M9-$O9) | Q9: =IF($D9="","",IF($I9>0,$P9/$I9,""))
E10: =IF($D10="","",IFERROR(INDEX(INVENTARIO!$C$7:$C$26,MATCH($D10,INVENTARIO!$B$7:$B$26,0)),"⚠ ID no existe")) | H10: =IF($D10="","",IF($G10="",IFERROR(INDEX(INVENTARIO!$N$7:$N$26,MATCH($D10,INVENTARIO!$B$7:$B$26,0)),""),$G10)) | I10: =IF($D10="","",N($F10)*IF(ISNUMBER($H10),$H10,0)) | J10: =IF($D10="","",IFERROR(IF(INDEX(INVENTARIO!$O$7:$O$26,MATCH($D10,INVENTARIO!$B$7:$B$26,0))="",CFG_WALMART,INDEX(INVENTARIO!$O$7:$O$26,MATCH($D10,INVENTARIO!$B$7:$B$26,0))),CFG_WALMART)) | K10: =IF($D10="","",$I10*$J10) | M10: =IF($D10="","",$I10-$K10-N($L10)) | N10: =IF($D10="","",IFERROR(INDEX(INVENTARIO!$L$7:$L$26,MATCH($D10,INVENTARIO!$B$7:$B$26,0))*1,0)) | O10: =IF($D10="","",N($F10)*$N10) | P10: =IF($D10="","",$M10-$O10) | Q10: =IF($D10="","",IF($I10>0,$P10/$I10,""))
E11: =IF($D11="","",IFERROR(INDEX(INVENTARIO!$C$7:$C$26,MATCH($D11,INVENTARIO!$B$7:$B$26,0)),"⚠ ID no existe")) | H11: =IF($D11="","",IF($G11="",IFERROR(INDEX(INVENTARIO!$N$7:$N$26,MATCH($D11,INVENTARIO!$B$7:$B$26,0)),""),$G11)) | I11: =IF($D11="","",N($F11)*IF(ISNUMBER($H11),$H11,0)) | J11: =IF($D11="","",IFERROR(IF(INDEX(INVENTARIO!$O$7:$O$26,MATCH($D11,INVENTARIO!$B$7:$B$26,0))="",CFG_WALMART,INDEX(INVENTARIO!$O$7:$O$26,MATCH($D11,INVENTARIO!$B$7:$B$26,0))),CFG_WALMART)) | K11: =IF($D11="","",$I11*$J11) | M11: =IF($D11="","",$I11-$K11-N($L11)) | N11: =IF($D11="","",IFERROR(INDEX(INVENTARIO!$L$7:$L$26,MATCH($D11,INVENTARIO!$B$7:$B$26,0))*1,0)) | O11: =IF($D11="","",N($F11)*$N11) | P11: =IF($D11="","",$M11-$O11) | Q11: =IF($D11="","",IF($I11>0,$P11/$I11,""))
E12: =IF($D12="","",IFERROR(INDEX(INVENTARIO!$C$7:$C$26,MATCH($D12,INVENTARIO!$B$7:$B$26,0)),"⚠ ID no existe")) | H12: =IF($D12="","",IF($G12="",IFERROR(INDEX(INVENTARIO!$N$7:$N$26,MATCH($D12,INVENTARIO!$B$7:$B$26,0)),""),$G12)) | I12: =IF($D12="","",N($F12)*IF(ISNUMBER($H12),$H12,0)) | J12: =IF($D12="","",IFERROR(IF(INDEX(INVENTARIO!$O$7:$O$26,MATCH($D12,INVENTARIO!$B$7:$B$26,0))="",CFG_WALMART,INDEX(INVENTARIO!$O$7:$O$26,MATCH($D12,INVENTARIO!$B$7:$B$26,0))),CFG_WALMART)) | K12: =IF($D12="","",$I12*$J12) | M12: =IF($D12="","",$I12-$K12-N($L12)) | N12: =IF($D12="","",IFERROR(INDEX(INVENTARIO!$L$7:$L$26,MATCH($D12,INVENTARIO!$B$7:$B$26,0))*1,0)) | O12: =IF($D12="","",N($F12)*$N12) | P12: =IF($D12="","",$M12-$O12) | Q12: =IF($D12="","",IF($I12>0,$P12/$I12,""))
E13: =IF($D13="","",IFERROR(INDEX(INVENTARIO!$C$7:$C$26,MATCH($D13,INVENTARIO!$B$7:$B$26,0)),"⚠ ID no existe")) | H13: =IF($D13="","",IF($G13="",IFERROR(INDEX(INVENTARIO!$N$7:$N$26,MATCH($D13,INVENTARIO!$B$7:$B$26,0)),""),$G13)) | I13: =IF($D13="","",N($F13)*IF(ISNUMBER($H13),$H13,0)) | J13: =IF($D13="","",IFERROR(IF(INDEX(INVENTARIO!$O$7:$O$26,MATCH($D13,INVENTARIO!$B$7:$B$26,0))="",CFG_WALMART,INDEX(INVENTARIO!$O$7:$O$26,MATCH($D13,INVENTARIO!$B$7:$B$26,0))),CFG_WALMART)) | K13: =IF($D13="","",$I13*$J13) | M13: =IF($D13="","",$I13-$K13-N($L13)) | N13: =IF($D13="","",IFERROR(INDEX(INVENTARIO!$L$7:$L$26,MATCH($D13,INVENTARIO!$B$7:$B$26,0))*1,0)) | O13: =IF($D13="","",N($F13)*$N13) | P13: =IF($D13="","",$M13-$O13) | Q13: =IF($D13="","",IF($I13>0,$P13/$I13,""))
E14: =IF($D14="","",IFERROR(INDEX(INVENTARIO!$C$7:$C$26,MATCH($D14,INVENTARIO!$B$7:$B$26,0)),"⚠ ID no existe")) | H14: =IF($D14="","",IF($G14="",IFERROR(INDEX(INVENTARIO!$N$7:$N$26,MATCH($D14,INVENTARIO!$B$7:$B$26,0)),""),$G14)) | I14: =IF($D14="","",N($F14)*IF(ISNUMBER($H14),$H14,0)) | J14: =IF($D14="","",IFERROR(IF(INDEX(INVENTARIO!$O$7:$O$26,MATCH($D14,INVENTARIO!$B$7:$B$26,0))="",CFG_WALMART,INDEX(INVENTARIO!$O$7:$O$26,MATCH($D14,INVENTARIO!$B$7:$B$26,0))),CFG_WALMART)) | K14: =IF($D14="","",$I14*$J14) | M14: =IF($D14="","",$I14-$K14-N($L14)) | N14: =IF($D14="","",IFERROR(INDEX(INVENTARIO!$L$7:$L$26,MATCH($D14,INVENTARIO!$B$7:$B$26,0))*1,0)) | O14: =IF($D14="","",N($F14)*$N14) | P14: =IF($D14="","",$M14-$O14) | Q14: =IF($D14="","",IF($I14>0,$P14/$I14,""))
E15: =IF($D15="","",IFERROR(INDEX(INVENTARIO!$C$7:$C$26,MATCH($D15,INVENTARIO!$B$7:$B$26,0)),"⚠ ID no existe")) | H15: =IF($D15="","",IF($G15="",IFERROR(INDEX(INVENTARIO!$N$7:$N$26,MATCH($D15,INVENTARIO!$B$7:$B$26,0)),""),$G15)) | I15: =IF($D15="","",N($F15)*IF(ISNUMBER($H15),$H15,0)) | J15: =IF($D15="","",IFERROR(IF(INDEX(INVENTARIO!$O$7:$O$26,MATCH($D15,INVENTARIO!$B$7:$B$26,0))="",CFG_WALMART,INDEX(INVENTARIO!$O$7:$O$26,MATCH($D15,INVENTARIO!$B$7:$B$26,0))),CFG_WALMART)) | K15: =IF($D15="","",$I15*$J15) | M15: =IF($D15="","",$I15-$K15-N($L15)) | N15: =IF($D15="","",IFERROR(INDEX(INVENTARIO!$L$7:$L$26,MATCH($D15,INVENTARIO!$B$7:$B$26,0))*1,0)) | O15: =IF($D15="","",N($F15)*$N15) | P15: =IF($D15="","",$M15-$O15) | Q15: =IF($D15="","",IF($I15>0,$P15/$I15,""))
E16: =IF($D16="","",IFERROR(INDEX(INVENTARIO!$C$7:$C$26,MATCH($D16,INVENTARIO!$B$7:$B$26,0)),"⚠ ID no existe")) | H16: =IF($D16="","",IF($G16="",IFERROR(INDEX(INVENTARIO!$N$7:$N$26,MATCH($D16,INVENTARIO!$B$7:$B$26,0)),""),$G16)) | I16: =IF($D16="","",N($F16)*IF(ISNUMBER($H16),$H16,0)) | J16: =IF($D16="","",IFERROR(IF(INDEX(INVENTARIO!$O$7:$O$26,MATCH($D16,INVENTARIO!$B$7:$B$26,0))="",CFG_WALMART,INDEX(INVENTARIO!$O$7:$O$26,MATCH($D16,INVENTARIO!$B$7:$B$26,0))),CFG_WALMART)) | K16: =IF($D16="","",$I16*$J16) | M16: =IF($D16="","",$I16-$K16-N($L16)) | N16: =IF($D16="","",IFERROR(INDEX(INVENTARIO!$L$7:$L$26,MATCH($D16,INVENTARIO!$B$7:$B$26,0))*1,0)) | O16: =IF($D16="","",N($F16)*$N16) | P16: =IF($D16="","",$M16-$O16) | Q16: =IF($D16="","",IF($I16>0,$P16/$I16,""))
E17: =IF($D17="","",IFERROR(INDEX(INVENTARIO!$C$7:$C$26,MATCH($D17,INVENTARIO!$B$7:$B$26,0)),"⚠ ID no existe")) | H17: =IF($D17="","",IF($G17="",IFERROR(INDEX(INVENTARIO!$N$7:$N$26,MATCH($D17,INVENTARIO!$B$7:$B$26,0)),""),$G17)) | I17: =IF($D17="","",N($F17)*IF(ISNUMBER($H17),$H17,0)) | J17: =IF($D17="","",IFERROR(IF(INDEX(INVENTARIO!$O$7:$O$26,MATCH($D17,INVENTARIO!$B$7:$B$26,0))="",CFG_WALMART,INDEX(INVENTARIO!$O$7:$O$26,MATCH($D17,INVENTARIO!$B$7:$B$26,0))),CFG_WALMART)) | K17: =IF($D17="","",$I17*$J17) | M17: =IF($D17="","",$I17-$K17-N($L17)) | N17: =IF($D17="","",IFERROR(INDEX(INVENTARIO!$L$7:$L$26,MATCH($D17,INVENTARIO!$B$7:$B$26,0))*1,0)) | O17: =IF($D17="","",N($F17)*$N17) | P17: =IF($D17="","",$M17-$O17) | Q17: =IF($D17="","",IF($I17>0,$P17/$I17,""))
... E505: =IF($D505="","",IFERROR(INDEX(INVENTARIO!$C$7:$C$26,MATCH($D505,INVENTARIO!$B$7:$B$26,0)),"⚠ ID no existe")) | H505: =IF($D505="","",IF($G505="",IFERROR(INDEX(INVENTARIO!$N$7:$N$26,MATCH($D505,INVENTARIO!$B$7:$B$26,0)),""),$G505)) | I505: =IF($D505="","",N($F505)*IF(ISNUMBER($H505),$H505,0)) | J505: =IF($D505="","",IFERROR(IF(INDEX(INVENTARIO!$O$7:$O$26,MATCH($D505,INVENTARIO!$B$7:$B$26,0))="",CFG_WALMART,INDEX(INVENTARIO!$O$7:$O$26,MATCH($D505,INVENTARIO!$B$7:$B$26,0))),CFG_WALMART)) | K505: =IF($D505="","",$I505*$J505) | M505: =IF($D505="","",$I505-$K505-N($L505)) | N505: =IF($D505="","",IFERROR(INDEX(INVENTARIO!$L$7:$L$26,MATCH($D505,INVENTARIO!$B$7:$B$26,0))*1,0)) | O505: =IF($D505="","",N($F505)*$N505) | P505: =IF($D505="","",$M505-$O505) | Q505: =IF($D505="","",IF($I505>0,$P505/$I505,""))
B506: TOTAL | F506: =SUM(F6:F505) | I506: =SUM(I6:I505) | K506: =SUM(K6:K505) | L506: =SUM(L6:L505) | M506: =SUM(M6:M505) | O506: =SUM(O6:O505) | P506: =SUM(P6:P505) | Q506: =IF(I506>0,P506/I506,0)

Sheet GASTOS
B1: COTIMIX · REGISTRO DE GASTOS OPERATIVOS
B2: Publicidad, envíos, empaques, suscripciones, etc. Pagos con Citi suman automáticamente el 2.9%.
B4: 'Descontado por Walmart' = cargos que Walmart resta de su liquidación (no salen del banco).
B5: Fecha | C5: Categoría | D5: Descripción | E5: Proveedor | F5: Método de pago | G5: Monto | H5: Recargo tarjeta % | I5: Recargo tarjeta $ | J5: TOTAL REAL | K5: Notas
H6: =IF(N($G6)=0,"",IF($F6="Tarjeta Citi",CFG_CITI,0)) | I6: =IF(N($G6)=0,"",$G6*$H6) | J6: =IF(N($G6)=0,"",$G6+$I6)
H7: =IF(N($G7)=0,"",IF($F7="Tarjeta Citi",CFG_CITI,0)) | I7: =IF(N($G7)=0,"",$G7*$H7) | J7: =IF(N($G7)=0,"",$G7+$I7)
H8: =IF(N($G8)=0,"",IF($F8="Tarjeta Citi",CFG_CITI,0)) | I8: =IF(N($G8)=0,"",$G8*$H8) | J8: =IF(N($G8)=0,"",$G8+$I8)
H9: =IF(N($G9)=0,"",IF($F9="Tarjeta Citi",CFG_CITI,0)) | I9: =IF(N($G9)=0,"",$G9*$H9) | J9: =IF(N($G9)=0,"",$G9+$I9)
H10: =IF(N($G10)=0,"",IF($F10="Tarjeta Citi",CFG_CITI,0)) | I10: =IF(N($G10)=0,"",$G10*$H10) | J10: =IF(N($G10)=0,"",$G10+$I10)
H11: =IF(N($G11)=0,"",IF($F11="Tarjeta Citi",CFG_CITI,0)) | I11: =IF(N($G11)=0,"",$G11*$H11) | J11: =IF(N($G11)=0,"",$G11+$I11)
H12: =IF(N($G12)=0,"",IF($F12="Tarjeta Citi",CFG_CITI,0)) | I12: =IF(N($G12)=0,"",$G12*$H12) | J12: =IF(N($G12)=0,"",$G12+$I12)
H13: =IF(N($G13)=0,"",IF($F13="Tarjeta Citi",CFG_CITI,0)) | I13: =IF(N($G13)=0,"",$G13*$H13) | J13: =IF(N($G13)=0,"",$G13+$I13)
H14: =IF(N($G14)=0,"",IF($F14="Tarjeta Citi",CFG_CITI,0)) | I14: =IF(N($G14)=0,"",$G14*$H14) | J14: =IF(N($G14)=0,"",$G14+$I14)
H15: =IF(N($G15)=0,"",IF($F15="Tarjeta Citi",CFG_CITI,0)) | I15: =IF(N($G15)=0,"",$G15*$H15) | J15: =IF(N($G15)=0,"",$G15+$I15)
H16: =IF(N($G16)=0,"",IF($F16="Tarjeta Citi",CFG_CITI,0)) | I16: =IF(N($G16)=0,"",$G16*$H16) | J16: =IF(N($G16)=0,"",$G16+$I16)
H17: =IF(N($G17)=0,"",IF($F17="Tarjeta Citi",CFG_CITI,0)) | I17: =IF(N($G17)=0,"",$G17*$H17) | J17: =IF(N($G17)=0,"",$G17+$I17)
... H305: =IF(N($G305)=0,"",IF($F305="Tarjeta Citi",CFG_CITI,0)) | I305: =IF(N($G305)=0,"",$G305*$H305) | J305: =IF(N($G305)=0,"",$G305+$I305)
B306: TOTAL | G306: =SUM(G6:G305) | I306: =SUM(I6:I305) | J306: =SUM(J6:J305)

Sheet WALMART
B1: COTIMIX · CUENTA WALMART MARKETPLACE Y RESERVA
B2: Dinero de COTIMIX que está en Walmart: separa la RESERVA (no disponible) del saldo por liquidar.
B5: A. RESERVA WALMART (dinero de COTIMIX, NO disponible)
B6: Reserva al inicio (CONFIG) | E6: =CFG_RESERVA
B7: (+) Retenciones enviadas a reserva | E7: =SUMIFS(WALMART!$E$22:$E$321,WALMART!$C$22:$C$321,"Retención a reserva")
B8: (−) Liberaciones de reserva | E8: =-SUMIFS(WALMART!$E$22:$E$321,WALMART!$C$22:$C$321,"Liberación de reserva")
B9: SALDO EN RESERVA (no disponible) | E9: =SUM(E6:E8)
B11: B. SALDO TOTAL A FAVOR EN WALMART
B12: Reserva al inicio (CONFIG) | E12: =CFG_RESERVA
B13: (+) Ingresos netos de ventas | E13: =SUM(VENTAS!$M$6:$M$505) | F13: Venta bruta − comisión − cargos (hoja VENTAS)
B14: (−) Depósitos recibidos en banco | E14: =-SUMIFS(WALMART!$E$22:$E$321,WALMART!$C$22:$C$321,"Depósito a banco")
B15: (−) Cargos descontados por Walmart | E15: =-SUMIFS(GASTOS!$J$6:$J$305,GASTOS!$F$6:$F$305,"Descontado por Walmart") | F15: Desde hoja GASTOS
B16: SALDO TOTAL A FAVOR EN WALMART | E16: =SUM(E12:E15)
B17: de los cuales: en reserva (no disponible) | E17: =E9
B18: de los cuales: por liquidar (próximo depósito) | E18: =E16-E17
B20: MOVIMIENTOS · capture aquí retenciones, liberaciones y depósitos que Walmart envía a su banco (montos siempre positivos)
B21: Fecha | C21: Tipo de movimiento | D21: Referencia / Descripción | E21: Monto (USD) | F21: Notas

Sheet BANCO
B1: COTIMIX · BANCO / EFECTIVO Y TARJETA CITI
B2: Saldo de efectivo disponible y deuda de la tarjeta Citi, calculados desde todos los registros.
B5: A. EFECTIVO / BANCO DISPONIBLE
B6: (+) Aportes de capital | E6: =SUMIFS(BANCO!$E$22:$E$321,BANCO!$C$22:$C$321,"Aporte de capital")
B7: (+) Depósitos recibidos de Walmart | E7: =-WALMART!E14 | F7: Desde hoja WALMART
B8: (+) Otros ingresos | E8: =SUMIFS(BANCO!$E$22:$E$321,BANCO!$C$22:$C$321,"Otro ingreso")
B9: (−) Retiros del propietario | E9: =-SUMIFS(BANCO!$E$22:$E$321,BANCO!$C$22:$C$321,"Retiro del propietario")
B10: (−) Pagos a tarjeta Citi | E10: =-SUMIFS(BANCO!$E$22:$E$321,BANCO!$C$22:$C$321,"Pago tarjeta Citi")
B11: (−) Compras de inventario pagadas en efectivo | E11: =-SUMIFS(COMPRAS!$L$6:$L$305,COMPRAS!$I$6:$I$305,"Efectivo/Banco") | F11: Desde hoja COMPRAS
B12: (−) Gastos pagados en efectivo | E12: =-SUMIFS(GASTOS!$J$6:$J$305,GASTOS!$F$6:$F$305,"Efectivo/Banco") | F12: Desde hoja GASTOS
B13: SALDO DE EFECTIVO DISPONIBLE | E13: =SUM(E6:E12)
B15: B. TARJETA DE CRÉDITO CITI (pasivo)
B16: (+) Compras de inventario con Citi (incl. 2.9%) | E16: =SUMIFS(COMPRAS!$L$6:$L$305,COMPRAS!$I$6:$I$305,"Tarjeta Citi")
B17: (+) Gastos pagados con Citi (incl. 2.9%) | E17: =SUMIFS(GASTOS!$J$6:$J$305,GASTOS!$F$6:$F$305,"Tarjeta Citi")
B18: (−) Pagos realizados a Citi | E18: =E10
B19: SALDO POR PAGAR A CITI | E19: =SUM(E16:E18)
B21: Fecha | C21: Tipo de movimiento | D21: Referencia / Descripción | E21: Monto (USD) | F21: Notas
B22: =CFG_FECHA | C22: Aporte de capital | D22: Capital inicial invertido COTIMIX | E22: =CFG_CAPITAL | F22: Vinculado a CONFIG (no editar aquí)

Sheet ESTADO_RESULTADOS
B1: COTIMIX · ESTADO DE RESULTADOS MENSUAL
B2: Se genera automáticamente desde VENTAS, GASTOS y BANCO. Cambie el año en CONFIG.
B4: ="Ejercicio "&CFG_ANIO&" · cifras en USD"
C5: =DATE(CFG_ANIO,1,1) | D5: =DATE(CFG_ANIO,2,1) | E5: =DATE(CFG_ANIO,3,1) | F5: =DATE(CFG_ANIO,4,1) | G5: =DATE(CFG_ANIO,5,1) | H5: =DATE(CFG_ANIO,6,1) | I5: =DATE(CFG_ANIO,7,1) | J5: =DATE(CFG_ANIO,8,1) | K5: =DATE(CFG_ANIO,9,1) | L5: =DATE(CFG_ANIO,10,1) | M5: =DATE(CFG_ANIO,11,1) | N5: =DATE(CFG_ANIO,12,1)
B6: Concepto | C6: ENE | D6: FEB | E6: MAR | F6: ABR | G6: MAY | H6: JUN | I6: JUL | J6: AGO | K6: SEP | L6: OCT | M6: NOV | N6: DIC | O6: TOTAL AÑO | Q6: ACUMULADO HISTÓRICO
B7: INGRESOS
B8: Ventas brutas | C8: =SUMIFS(VENTAS!$I$6:$I$505,VENTAS!$B$6:$B$505,">="&C$5,VENTAS!$B$6:$B$505,"<"&DATE(YEAR(C$5),MONTH(C$5)+1,1)) | D8: =SUMIFS(VENTAS!$I$6:$I$505,VENTAS!$B$6:$B$505,">="&D$5,VENTAS!$B$6:$B$505,"<"&DATE(YEAR(D$5),MONTH(D$5)+1,1)) | E8: =SUMIFS(VENTAS!$I$6:$I$505,VENTAS!$B$6:$B$505,">="&E$5,VENTAS!$B$6:$B$505,"<"&DATE(YEAR(E$5),MONTH(E$5)+1,1)) | F8: =SUMIFS(VENTAS!$I$6:$I$505,VENTAS!$B$6:$B$505,">="&F$5,VENTAS!$B$6:$B$505,"<"&DATE(YEAR(F$5),MONTH(F$5)+1,1)) | G8: =SUMIFS(VENTAS!$I$6:$I$505,VENTAS!$B$6:$B$505,">="&G$5,VENTAS!$B$6:$B$505,"<"&DATE(YEAR(G$5),MONTH(G$5)+1,1)) | H8: =SUMIFS(VENTAS!$I$6:$I$505,VENTAS!$B$6:$B$505,">="&H$5,VENTAS!$B$6:$B$505,"<"&DATE(YEAR(H$5),MONTH(H$5)+1,1)) | I8: =SUMIFS(VENTAS!$I$6:$I$505,VENTAS!$B$6:$B$505,">="&I$5,VENTAS!$B$6:$B$505,"<"&DATE(YEAR(I$5),MONTH(I$5)+1,1)) | J8: =SUMIFS(VENTAS!$I$6:$I$505,VENTAS!$B$6:$B$505,">="&J$5,VENTAS!$B$6:$B$505,"<"&DATE(YEAR(J$5),MONTH(J$5)+1,1)) | ... N8: =SUMIFS(VENTAS!$I$6:$I$505,VENTAS!$B$6:$B$505,">="&N$5,VENTAS!$B$6:$B$505,"<"&DATE(YEAR(N$5),MONTH(N$5)+1,1)) | O8: =SUM(C8:N8) | Q8: =SUM(VENTAS!$I$6:$I$505)
B9: (−) Comisiones Walmart | C9: =-SUMIFS(VENTAS!$K$6:$K$505,VENTAS!$B$6:$B$505,">="&C$5,VENTAS!$B$6:$B$505,"<"&DATE(YEAR(C$5),MONTH(C$5)+1,1)) | D9: =-SUMIFS(VENTAS!$K$6:$K$505,VENTAS!$B$6:$B$505,">="&D$5,VENTAS!$B$6:$B$505,"<"&DATE(YEAR(D$5),MONTH(D$5)+1,1)) | E9: =-SUMIFS(VENTAS!$K$6:$K$505,VENTAS!$B$6:$B$505,">="&E$5,VENTAS!$B$6:$B$505,"<"&DATE(YEAR(E$5),MONTH(E$5)+1,1)) | F9: =-SUMIFS(VENTAS!$K$6:$K$505,VENTAS!$B$6:$B$505,">="&F$5,VENTAS!$B$6:$B$505,"<"&DATE(YEAR(F$5),MONTH(F$5)+1,1)) | G9: =-SUMIFS(VENTAS!$K$6:$K$505,VENTAS!$B$6:$B$505,">="&G$5,VENTAS!$B$6:$B$505,"<"&DATE(YEAR(G$5),MONTH(G$5)+1,1)) | H9: =-SUMIFS(VENTAS!$K$6:$K$505,VENTAS!$B$6:$B$505,">="&H$5,VENTAS!$B$6:$B$505,"<"&DATE(YEAR(H$5),MONTH(H$5)+1,1)) | I9: =-SUMIFS(VENTAS!$K$6:$K$505,VENTAS!$B$6:$B$505,">="&I$5,VENTAS!$B$6:$B$505,"<"&DATE(YEAR(I$5),MONTH(I$5)+1,1)) | J9: =-SUMIFS(VENTAS!$K$6:$K$505,VENTAS!$B$6:$B$505,">="&J$5,VENTAS!$B$6:$B$505,"<"&DATE(YEAR(J$5),MONTH(J$5)+1,1)) | ... N9: =-SUMIFS(VENTAS!$K$6:$K$505,VENTAS!$B$6:$B$505,">="&N$5,VENTAS!$B$6:$B$505,"<"&DATE(YEAR(N$5),MONTH(N$5)+1,1)) | O9: =SUM(C9:N9) | Q9: =-SUM(VENTAS!$K$6:$K$505)
B10: (−) Envíos y cargos Walmart | C10: =-SUMIFS(VENTAS!$L$6:$L$505,VENTAS!$B$6:$B$505,">="&C$5,VENTAS!$B$6:$B$505,"<"&DATE(YEAR(C$5),MONTH(C$5)+1,1)) | D10: =-SUMIFS(VENTAS!$L$6:$L$505,VENTAS!$B$6:$B$505,">="&D$5,VENTAS!$B$6:$B$505,"<"&DATE(YEAR(D$5),MONTH(D$5)+1,1)) | E10: =-SUMIFS(VENTAS!$L$6:$L$505,VENTAS!$B$6:$B$505,">="&E$5,VENTAS!$B$6:$B$505,"<"&DATE(YEAR(E$5),MONTH(E$5)+1,1)) | F10: =-SUMIFS(VENTAS!$L$6:$L$505,VENTAS!$B$6:$B$505,">="&F$5,VENTAS!$B$6:$B$505,"<"&DATE(YEAR(F$5),MONTH(F$5)+1,1)) | G10: =-SUMIFS(VENTAS!$L$6:$L$505,VENTAS!$B$6:$B$505,">="&G$5,VENTAS!$B$6:$B$505,"<"&DATE(YEAR(G$5),MONTH(G$5)+1,1)) | H10: =-SUMIFS(VENTAS!$L$6:$L$505,VENTAS!$B$6:$B$505,">="&H$5,VENTAS!$B$6:$B$505,"<"&DATE(YEAR(H$5),MONTH(H$5)+1,1)) | I10: =-SUMIFS(VENTAS!$L$6:$L$505,VENTAS!$B$6:$B$505,">="&I$5,VENTAS!$B$6:$B$505,"<"&DATE(YEAR(I$5),MONTH(I$5)+1,1)) | J10: =-SUMIFS(VENTAS!$L$6:$L$505,VENTAS!$B$6:$B$505,">="&J$5,VENTAS!$B$6:$B$505,"<"&DATE(YEAR(J$5),MONTH(J$5)+1,1)) | ... N10: =-SUMIFS(VENTAS!$L$6:$L$505,VENTAS!$B$6:$B$505,">="&N$5,VENTAS!$B$6:$B$505,"<"&DATE(YEAR(N$5),MONTH(N$5)+1,1)) | O10: =SUM(C10:N10) | Q10: =-SUM(VENTAS!$L$6:$L$505)
B11: INGRESOS NETOS | C11: =SUM(C8:C10) | D11: =SUM(D8:D10) | E11: =SUM(E8:E10) | F11: =SUM(F8:F10) | G11: =SUM(G8:G10) | H11: =SUM(H8:H10) | I11: =SUM(I8:I10) | J11: =SUM(J8:J10) | ... N11: =SUM(N8:N10) | O11: =SUM(C11:N11) | Q11: =SUM(Q8:Q10)
B12: (−) Costo de ventas (costo real) | C12: =-SUMIFS(VENTAS!$O$6:$O$505,VENTAS!$B$6:$B$505,">="&C$5,VENTAS!$B$6:$B$505,"<"&DATE(YEAR(C$5),MONTH(C$5)+1,1)) | D12: =-SUMIFS(VENTAS!$O$6:$O$505,VENTAS!$B$6:$B$505,">="&D$5,VENTAS!$B$6:$B$505,"<"&DATE(YEAR(D$5),MONTH(D$5)+1,1)) | E12: =-SUMIFS(VENTAS!$O$6:$O$505,VENTAS!$B$6:$B$505,">="&E$5,VENTAS!$B$6:$B$505,"<"&DATE(YEAR(E$5),MONTH(E$5)+1,1)) | F12: =-SUMIFS(VENTAS!$O$6:$O$505,VENTAS!$B$6:$B$505,">="&F$5,VENTAS!$B$6:$B$505,"<"&DATE(YEAR(F$5),MONTH(F$5)+1,1)) | G12: =-SUMIFS(VENTAS!$O$6:$O$505,VENTAS!$B$6:$B$505,">="&G$5,VENTAS!$B$6:$B$505,"<"&DATE(YEAR(G$5),MONTH(G$5)+1,1)) | H12: =-SUMIFS(VENTAS!$O$6:$O$505,VENTAS!$B$6:$B$505,">="&H$5,VENTAS!$B$6:$B$505,"<"&DATE(YEAR(H$5),MONTH(H$5)+1,1)) | I12: =-SUMIFS(VENTAS!$O$6:$O$505,VENTAS!$B$6:$B$505,">="&I$5,VENTAS!$B$6:$B$505,"<"&DATE(YEAR(I$5),MONTH(I$5)+1,1)) | J12: =-SUMIFS(VENTAS!$O$6:$O$505,VENTAS!$B$6:$B$505,">="&J$5,VENTAS!$B$6:$B$505,"<"&DATE(YEAR(J$5),MONTH(J$5)+1,1)) | ... N12: =-SUMIFS(VENTAS!$O$6:$O$505,VENTAS!$B$6:$B$505,">="&N$5,VENTAS!$B$6:$B$505,"<"&DATE(YEAR(N$5),MONTH(N$5)+1,1)) | O12: =SUM(C12:N12) | Q12: =-SUM(VENTAS!$O$6:$O$505)
B13: UTILIDAD BRUTA | C13: =C11+C12 | D13: =D11+D12 | E13: =E11+E12 | F13: =F11+F12 | G13: =G11+G12 | H13: =H11+H12 | I13: =I11+I12 | J13: =J11+J12 | ... N13: =N11+N12 | O13: =SUM(C13:N13) | Q13: =Q11+Q12
B14: Margen bruto % | C14: =IF(C8>0,C13/C8,0) | D14: =IF(D8>0,D13/D8,0) | E14: =IF(E8>0,E13/E8,0) | F14: =IF(F8>0,F13/F8,0) | G14: =IF(G8>0,G13/G8,0) | H14: =IF(H8>0,H13/H8,0) | I14: =IF(I8>0,I13/I8,0) | J14: =IF(J8>0,J13/J8,0) | ... O14: =IF(O8>0,O13/O8,0) | Q14: =IF(Q8>0,Q13/Q8,0)
B15: GASTOS OPERATIVOS
B16: Publicidad (Walmart Sponsored) | C16: =-SUMIFS(GASTOS!$J$6:$J$305,GASTOS!$C$6:$C$305,"Publicidad (Walmart Sponsored)",GASTOS!$B$6:$B$305,">="&C$5,GASTOS!$B$6:$B$305,"<"&DATE(YEAR(C$5),MONTH(C$5)+1,1)) | D16: =-SUMIFS(GASTOS!$J$6:$J$305,GASTOS!$C$6:$C$305,"Publicidad (Walmart Sponsored)",GASTOS!$B$6:$B$305,">="&D$5,GASTOS!$B$6:$B$305,"<"&DATE(YEAR(D$5),MONTH(D$5)+1,1)) | E16: =-SUMIFS(GASTOS!$J$6:$J$305,GASTOS!$C$6:$C$305,"Publicidad (Walmart Sponsored)",GASTOS!$B$6:$B$305,">="&E$5,GASTOS!$B$6:$B$305,"<"&DATE(YEAR(E$5),MONTH(E$5)+1,1)) | F16: =-SUMIFS(GASTOS!$J$6:$J$305,GASTOS!$C$6:$C$305,"Publicidad (Walmart Sponsored)",GASTOS!$B$6:$B$305,">="&F$5,GASTOS!$B$6:$B$305,"<"&DATE(YEAR(F$5),MONTH(F$5)+1,1)) | G16: =-SUMIFS(GASTOS!$J$6:$J$305,GASTOS!$C$6:$C$305,"Publicidad (Walmart Sponsored)",GASTOS!$B$6:$B$305,">="&G$5,GASTOS!$B$6:$B$305,"<"&DATE(YEAR(G$5),MONTH(G$5)+1,1)) | H16: =-SUMIFS(GASTOS!$J$6:$J$305,GASTOS!$C$6:$C$305,"Publicidad (Walmart Sponsored)",GASTOS!$B$6:$B$305,">="&H$5,GASTOS!$B$6:$B$305,"<"&DATE(YEAR(H$5),MONTH(H$5)+1,1)) | I16: =-SUMIFS(GASTOS!$J$6:$J$305,GASTOS!$C$6:$C$305,"Publicidad (Walmart Sponsored)",GASTOS!$B$6:$B$305,">="&I$5,GASTOS!$B$6:$B$305,"<"&DATE(YEAR(I$5),MONTH(I$5)+1,1)) | J16: =-SUMIFS(GASTOS!$J$6:$J$305,GASTOS!$C$6:$C$305,"Publicidad (Walmart Sponsored)",GASTOS!$B$6:$B$305,">="&J$5,GASTOS!$B$6:$B$305,"<"&DATE(YEAR(J$5),MONTH(J$5)+1,1)) | ... N16: =-SUMIFS(GASTOS!$J$6:$J$305,GASTOS!$C$6:$C$305,"Publicidad (Walmart Sponsored)",GASTOS!$B$6:$B$305,">="&N$5,GASTOS!$B$6:$B$305,"<"&DATE(YEAR(N$5),MONTH(N$5)+1,1)) | O16: =SUM(C16:N16) | Q16: =-SUMIFS(GASTOS!$J$6:$J$305,GASTOS!$C$6:$C$305,"Publicidad (Walmart Sponsored)")
B17: Envíos y logística | C17: =-SUMIFS(GASTOS!$J$6:$J$305,GASTOS!$C$6:$C$305,"Envíos y logística",GASTOS!$B$6:$B$305,">="&C$5,GASTOS!$B$6:$B$305,"<"&DATE(YEAR(C$5),MONTH(C$5)+1,1)) | D17: =-SUMIFS(GASTOS!$J$6:$J$305,GASTOS!$C$6:$C$305,"Envíos y logística",GASTOS!$B$6:$B$305,">="&D$5,GASTOS!$B$6:$B$305,"<"&DATE(YEAR(D$5),MONTH(D$5)+1,1)) | E17: =-SUMIFS(GASTOS!$J$6:$J$305,GASTOS!$C$6:$C$305,"Envíos y logística",GASTOS!$B$6:$B$305,">="&E$5,GASTOS!$B$6:$B$305,"<"&DATE(YEAR(E$5),MONTH(E$5)+1,1)) | F17: =-SUMIFS(GASTOS!$J$6:$J$305,GASTOS!$C$6:$C$305,"Envíos y logística",GASTOS!$B$6:$B$305,">="&F$5,GASTOS!$B$6:$B$305,"<"&DATE(YEAR(F$5),MONTH(F$5)+1,1)) | G17: =-SUMIFS(GASTOS!$J$6:$J$305,GASTOS!$C$6:$C$305,"Envíos y logística",GASTOS!$B$6:$B$305,">="&G$5,GASTOS!$B$6:$B$305,"<"&DATE(YEAR(G$5),MONTH(G$5)+1,1)) | H17: =-SUMIFS(GASTOS!$J$6:$J$305,GASTOS!$C$6:$C$305,"Envíos y logística",GASTOS!$B$6:$B$305,">="&H$5,GASTOS!$B$6:$B$305,"<"&DATE(YEAR(H$5),MONTH(H$5)+1,1)) | I17: =-SUMIFS(GASTOS!$J$6:$J$305,GASTOS!$C$6:$C$305,"Envíos y logística",GASTOS!$B$6:$B$305,">="&I$5,GASTOS!$B$6:$B$305,"<"&DATE(YEAR(I$5),MONTH(I$5)+1,1)) | J17: =-SUMIFS(GASTOS!$J$6:$J$305,GASTOS!$C$6:$C$305,"Envíos y logística",GASTOS!$B$6:$B$305,">="&J$5,GASTOS!$B$6:$B$305,"<"&DATE(YEAR(J$5),MONTH(J$5)+1,1)) | ... N17: =-SUMIFS(GASTOS!$J$6:$J$305,GASTOS!$C$6:$C$305,"Envíos y logística",GASTOS!$B$6:$B$305,">="&N$5,GASTOS!$B$6:$B$305,"<"&DATE(YEAR(N$5),MONTH(N$5)+1,1)) | O17: =SUM(C17:N17) | Q17: =-SUMIFS(GASTOS!$J$6:$J$305,GASTOS!$C$6:$C$305,"Envíos y logística")
B18: Fulfillment / WFS | C18: =-SUMIFS(GASTOS!$J$6:$J$305,GASTOS!$C$6:$C$305,"Fulfillment / WFS",GASTOS!$B$6:$B$305,">="&C$5,GASTOS!$B$6:$B$305,"<"&DATE(YEAR(C$5),MONTH(C$5)+1,1)) | D18: =-SUMIFS(GASTOS!$J$6:$J$305,GASTOS!$C$6:$C$305,"Fulfillment / WFS",GASTOS!$B$6:$B$305,">="&D$5,GASTOS!$B$6:$B$305,"<"&DATE(YEAR(D$5),MONTH(D$5)+1,1)) | E18: =-SUMIFS(GASTOS!$J$6:$J$305,GASTOS!$C$6:$C$305,"Fulfillment / WFS",GASTOS!$B$6:$B$305,">="&E$5,GASTOS!$B$6:$B$305,"<"&DATE(YEAR(E$5),MONTH(E$5)+1,1)) | F18: =-SUMIFS(GASTOS!$J$6:$J$305,GASTOS!$C$6:$C$305,"Fulfillment / WFS",GASTOS!$B$6:$B$305,">="&F$5,GASTOS!$B$6:$B$305,"<"&DATE(YEAR(F$5),MONTH(F$5)+1,1)) | G18: =-SUMIFS(GASTOS!$J$6:$J$305,GASTOS!$C$6:$C$305,"Fulfillment / WFS",GASTOS!$B$6:$B$305,">="&G$5,GASTOS!$B$6:$B$305,"<"&DATE(YEAR(G$5),MONTH(G$5)+1,1)) | H18: =-SUMIFS(GASTOS!$J$6:$J$305,GASTOS!$C$6:$C$305,"Fulfillment / WFS",GASTOS!$B$6:$B$305,">="&H$5,GASTOS!$B$6:$B$305,"<"&DATE(YEAR(H$5),MONTH(H$5)+1,1)) | I18: =-SUMIFS(GASTOS!$J$6:$J$305,GASTOS!$C$6:$C$305,"Fulfillment / WFS",GASTOS!$B$6:$B$305,">="&I$5,GASTOS!$B$6:$B$305,"<"&DATE(YEAR(I$5),MONTH(I$5)+1,1)) | J18: =-SUMIFS(GASTOS!$J$6:$J$305,GASTOS!$C$6:$C$305,"Fulfillment / WFS",GASTOS!$B$6:$B$305,">="&J$5,GASTOS!$B$6:$B$305,"<"&DATE(YEAR(J$5),MONTH(J$5)+1,1)) | ... N18: =-SUMIFS(GASTOS!$J$6:$J$305,GASTOS!$C$6:$C$305,"Fulfillment / WFS",GASTOS!$B$6:$B$305,">="&N$5,GASTOS!$B$6:$B$305,"<"&DATE(YEAR(N$5),MONTH(N$5)+1,1)) | O18: =SUM(C18:N18) | Q18: =-SUMIFS(GASTOS!$J$6:$J$305,GASTOS!$C$6:$C$305,"Fulfillment / WFS")
